<?xml version="1.0" ?>
<!-- =================================================================================== -->
<!-- |    This document was autogenerated by xacro from my_car_1.urdf.xacro            | -->
<!-- |    EDITING THIS FILE BY HAND IS NOT RECOMMENDED                                 | -->
<!-- =================================================================================== -->
<!-- 按照先后顺序组合my_car -->
<robot name="my_car">
  <!-- 宏:黑色设置 -->
  <material name="black">
    <color rgba="0.0 0.0 0.0 1.0"/>
  </material>
  <!-- 质量  -->
  <!-- footprint -->
  <link name="base_footprint">
    <visual>
      <geometry>
        <sphere radius="0.001"/>
      </geometry>
    </visual>
  </link>
  <!-- 底盘 -->
  <link name="base_link">
    <visual>
      <geometry>
        <box size="0.15 0.25 0.06"/>
      </geometry>
      <origin rpy="0 0 0" xyz="0 0 0"/>
      <material name="yellow">
        <color rgba="0.5 0.3 0.0 0.5"/>
      </material>
    </visual>
    <collision>
      <geometry>
        <box size="0.15 0.25 0.06"/>
      </geometry>
      <origin rpy="0 0 0" xyz="0 0 0"/>
    </collision>
    <inertial>
      <mass value="5"/>
      <inertia ixx="0.010875000000000001" ixy="0" ixz="0" iyy="0.03541666666666666" iyz="0" izz="0.02754166666666667"/>
    </inertial>
  </link>
  <joint name="base_link2base_footprint" type="fixed">
    <parent link="base_footprint"/>
    <child link="base_link"/>
    <origin xyz="0 0 0.06"/>
  </joint>
  <link name="back_left_wheel">
    <visual>
      <geometry>
        <cylinder length="0.04" radius="0.03"/>
      </geometry>
      <origin rpy="1.5707963 0.0 0.0" xyz="0.0 0.0 0.0"/>
      <material name="black"/>
    </visual>
    <collision>
      <geometry>
        <cylinder length="0.04" radius="0.03"/>
      </geometry>
      <origin rpy="1.5707963 0.0 0.0" xyz="0.0 0.0 0.0"/>
    </collision>
    <inertial>
      <mass value="0.5"/>
      <inertia ixx="0.00017916666666666667" ixy="0" ixz="0" iyy="0.00017916666666666667" iyz="0" izz="0.000225"/>
    </inertial>
  </link>
  <joint name="back_left_wheel2base_link" type="continuous">
    <parent link="base_link"/>
    <child link="back_left_wheel"/>
    <origin xyz="-0.045 0.115 -0.030"/>
    <axis xyz="0 1 0"/>
    <dynamics damping="0.0"/>
    <limit effort="100" velocity="1000"/>
    <joint_properties damping="0.0" friction="0.0"/>
  </joint>
  <link name="back_right_wheel">
    <visual>
      <geometry>
        <cylinder length="0.04" radius="0.03"/>
      </geometry>
      <origin rpy="1.5707963 0.0 0.0" xyz="0.0 0.0 0.0"/>
      <material name="black"/>
    </visual>
    <collision>
      <geometry>
        <cylinder length="0.04" radius="0.03"/>
      </geometry>
      <origin rpy="1.5707963 0.0 0.0" xyz="0.0 0.0 0.0"/>
    </collision>
    <inertial>
      <mass value="0.5"/>
      <inertia ixx="0.00017916666666666667" ixy="0" ixz="0" iyy="0.00017916666666666667" iyz="0" izz="0.000225"/>
    </inertial>
  </link>
  <joint name="back_right_wheel2base_link" type="continuous">
    <parent link="base_link"/>
    <child link="back_right_wheel"/>
    <origin xyz="-0.045 -0.115 -0.030"/>
    <axis xyz="0 1 0"/>
    <dynamics damping="0.0"/>
    <limit effort="100" velocity="1000"/>
    <joint_properties damping="0.0" friction="0.0"/>
  </joint>
  <!-- 转向关节 -->
  <link name="front_left_wheel_joint">
    <visual>
      <geometry>
        <sphere radius="0.01"/>
      </geometry>
      <origin rpy="0.0 0.0 0.0" xyz="0.0 0.0 0.0"/>
      <material name="black"/>
    </visual>
    <collision>
      <geometry>
        <sphere radius="0.01"/>
      </geometry>
      <origin rpy="0.0 0.0 0.0" xyz="0.0 0.0 0.0"/>
    </collision>
    <inertial>
      <mass value="0.3"/>
      <inertia ixx="1.2e-05" ixy="0" ixz="0" iyy="1.2e-05" iyz="0" izz="1.2e-05"/>
    </inertial>
  </link>
  <joint name="front_left_wheel_joint2base_link" type="revolute">
    <parent link="base_link"/>
    <child link="front_left_wheel_joint"/>
    <origin xyz="0.045 0.115 0.0"/>
    <axis xyz="0 0 1"/>
    <!--阻尼系数0-->
    <dynamics damping="1.0"/>
    <!--effort最大力/力矩 v速度-->
    <limit effort="10" lower="-0.6" upper="0.6" velocity="1000"/>
    <!--damping阻尼系数 friction摩擦系数-->
    <joint_properties damping="1.0" friction="1.0"/>
  </joint>
  <!--转向轮-->
  <link name="front_left_wheel">
    <visual>
      <geometry>
        <cylinder length="0.04" radius="0.03"/>
      </geometry>
      <origin rpy="1.5707963 0.0 0.0" xyz="0.0 0.0 0.0"/>
      <material name="black"/>
    </visual>
    <collision>
      <geometry>
        <cylinder length="0.04" radius="0.03"/>
      </geometry>
      <origin rpy="1.5707963 0.0 0.0" xyz="0.0 0.0 0.0"/>
    </collision>
    <inertial>
      <mass value="0.5"/>
      <inertia ixx="0.00017916666666666667" ixy="0" ixz="0" iyy="0.00017916666666666667" iyz="0" izz="0.000225"/>
    </inertial>
  </link>
  <joint name="front_left_wheel2front_left_wheel_joint" type="continuous">
    <parent link="front_left_wheel_joint"/>
    <child link="front_left_wheel"/>
    <origin xyz="0 0 -0.030"/>
    <axis xyz="0 1 0"/>
    <dynamics damping="0.0"/>
    <limit effort="100" velocity="1000"/>
    <joint_properties damping="0.0" friction="0.0"/>
  </joint>
  <!-- 转向关节 -->
  <link name="front_right_wheel_joint">
    <visual>
      <geometry>
        <sphere radius="0.01"/>
      </geometry>
      <origin rpy="0.0 0.0 0.0" xyz="0.0 0.0 0.0"/>
      <material name="black"/>
    </visual>
    <collision>
      <geometry>
        <sphere radius="0.01"/>
      </geometry>
      <origin rpy="0.0 0.0 0.0" xyz="0.0 0.0 0.0"/>
    </collision>
    <inertial>
      <mass value="0.3"/>
      <inertia ixx="1.2e-05" ixy="0" ixz="0" iyy="1.2e-05" iyz="0" izz="1.2e-05"/>
    </inertial>
  </link>
  <joint name="front_right_wheel_joint2base_link" type="revolute">
    <parent link="base_link"/>
    <child link="front_right_wheel_joint"/>
    <origin xyz="0.045 -0.115 0.0"/>
    <axis xyz="0 0 1"/>
    <!--阻尼系数0-->
    <dynamics damping="1.0"/>
    <!--effort最大力/力矩 v速度-->
    <limit effort="10" lower="-0.6" upper="0.6" velocity="1000"/>
    <!--damping阻尼系数 friction摩擦系数-->
    <joint_properties damping="1.0" friction="1.0"/>
  </joint>
  <!--转向轮-->
  <link name="front_right_wheel">
    <visual>
      <geometry>
        <cylinder length="0.04" radius="0.03"/>
      </geometry>
      <origin rpy="1.5707963 0.0 0.0" xyz="0.0 0.0 0.0"/>
      <material name="black"/>
    </visual>
    <collision>
      <geometry>
        <cylinder length="0.04" radius="0.03"/>
      </geometry>
      <origin rpy="1.5707963 0.0 0.0" xyz="0.0 0.0 0.0"/>
    </collision>
    <inertial>
      <mass value="0.5"/>
      <inertia ixx="0.00017916666666666667" ixy="0" ixz="0" iyy="0.00017916666666666667" iyz="0" izz="0.000225"/>
    </inertial>
  </link>
  <joint name="front_right_wheel2front_right_wheel_joint" type="continuous">
    <parent link="front_right_wheel_joint"/>
    <child link="front_right_wheel"/>
    <origin xyz="0 0 -0.030"/>
    <axis xyz="0 1 0"/>
    <dynamics damping="0.0"/>
    <limit effort="100" velocity="1000"/>
    <joint_properties damping="0.0" friction="0.0"/>
  </joint>
  <gazebo reference="base_footprint">
    <turnGravityOff>false</turnGravityOff>
    <!--关闭重力-->
  </gazebo>
  <gazebo reference="base_link">
    <material>Gazebo/Yellow</material>
  </gazebo>
  <gazebo reference="back_right_wheel">
    <material>Gazebo/Red</material>
    <!--mu1静态摩擦系数 mu2动态摩擦系数-->
    <mu1 value="2.0"/>
    <mu2 value="2.0"/>
    <!--弹簧系数，数值越大，轮子与地面之间的反作用力越强，轮子回弹得越快-->
    <kp value="10000000.0"/>
    <!--阻尼系数，模拟物体在接触表面上的阻尼力，控制物体在接触时的速度变化-->
    <kd value="1.0"/>
    <!--接触力，这里模拟摩擦力沿x方向-->
    <fdir1 value="1 0 0"/>
  </gazebo>
  <gazebo reference="back_left_wheel">
    <material>Gazebo/Red</material>
    <!--mu1静态摩擦系数 mu2动态摩擦系数-->
    <mu1 value="2.0"/>
    <mu2 value="2.0"/>
    <!--弹簧系数，数值越大，轮子与地面之间的反作用力越强，轮子回弹得越快-->
    <kp value="10000000.0"/>
    <!--阻尼系数，模拟物体在接触表面上的阻尼力，控制物体在接触时的速度变化-->
    <kd value="1.0"/>
    <!--接触力，这里模拟主动轮摩擦力沿x方向-->
    <fdir1 value="1 0 0"/>
  </gazebo>
  <gazebo reference="front_right_wheel">
    <material>Gazebo/Red</material>
    <!--mu1静态摩擦系数 mu2动态摩擦系数-->
    <mu1 value="2.0"/>
    <mu2 value="2.0"/>
    <!--弹簧系数，数值越大，轮子与地面之间的反作用力越强，轮子回弹得越快-->
    <kp value="10000000.0"/>
    <!--阻尼系数，模拟物体在接触表面上的阻尼力，控制物体在接触时的速度变化-->
    <kd value="1.0"/>
    <!--接触力，这里模拟被动轮支撑力沿z方向-->
    <fdir1 value="0 0 1"/>
  </gazebo>
  <gazebo reference="front_left_wheel">
    <material>Gazebo/Red</material>
    <!--mu1静态摩擦系数 mu2动态摩擦系数-->
    <mu1 value="2.0"/>
    <mu2 value="2.0"/>
    <!--弹簧系数，数值越大，轮子与地面之间的反作用力越强，轮子回弹得越快-->
    <kp value="10000000.0"/>
    <!--阻尼系数，模拟物体在接触表面上的阻尼力，控制物体在接触时的速度变化-->
    <kd value="1.0"/>
    <!--接触力，这里模拟被动轮支撑力沿z方向-->
    <fdir1 value="0 0 1"/>
  </gazebo>
  <gazebo reference="front_left_wheel_joint">
    <material>Gazebo/Black</material>
    <mu1 value="2.0"/>
    <mu2 value="2.0"/>
    <!--弹簧系数，数值越大，轮子与地面之间的反作用力越强，轮子回弹得越快-->
    <kp value="10000000.0"/>
    <!--阻尼系数，模拟物体在接触表面上的阻尼力，控制物体在接触时的速度变化-->
    <kd value="1.0"/>
    <!--接触力，这里模拟被动轮支撑力沿z方向-->
    <fdir1 value="1 0 0"/>
  </gazebo>
  <gazebo reference="front_right_wheel_joint">
    <material>Gazebo/Black</material>
    <mu1 value="2.0"/>
    <mu2 value="2.0"/>
    <!--弹簧系数，数值越大，轮子与地面之间的反作用力越强，轮子回弹得越快-->
    <kp value="10000000.0"/>
    <!--阻尼系数，模拟物体在接触表面上的阻尼力，控制物体在接触时的速度变化-->
    <kd value="1.0"/>
    <!--接触力，这里模拟被动轮支撑力沿z方向-->
    <fdir1 value="1 0 0"/>
  </gazebo>
  <!--传动模型-->
  <transmission name="front_right_wheel_joint2base_link_trans">
    <!--SimpleTransmission电机扭矩传递给关节-->
    <type>transmission_interface/SimpleTransmission</type>
    <joint name="front_right_wheel_joint2base_link">
      <hardwareInterface>hardware_interface/EffortJointInterface</hardwareInterface>
    </joint>
    <actuator name="front_right_wheel_joint_motor">
      <!--硬件接口类型 EffortJointInterface执行器通过扭矩控制-->
      <hardwareInterface>hardware_interface/EffortJointInterface</hardwareInterface>
      <!--减速比-->
      <mechanicalReduction>1</mechanicalReduction>
      <!--单位电流下产生的扭矩-->
      <motorTorqueConstant>100</motorTorqueConstant>
    </actuator>
  </transmission>
  <transmission name="front_left_wheel_joint2base_link_trans">
    <type>transmission_interface/SimpleTransmission</type>
    <joint name="front_left_wheel_joint2base_link">
      <hardwareInterface>hardware_interface/EffortJointInterface</hardwareInterface>
    </joint>
    <actuator name="front_left_wheel_joint_motor">
      <hardwareInterface>hardware_interface/EffortJointInterface</hardwareInterface>
      <mechanicalReduction>1</mechanicalReduction>
      <motorTorqueConstant>100</motorTorqueConstant>
    </actuator>
  </transmission>
  <transmission name="back_right_wheel2base_link_trans">
    <type>transmission_interface/SimpleTransmission</type>
    <joint name="back_right_wheel2base_link">
      <hardwareInterface>hardware_interface/VelocityJointInterface</hardwareInterface>
    </joint>
    <actuator name="back_right_wheel_joint_motor">
      <hardwareInterface>hardware_interface/VelocityJointInterface</hardwareInterface>
      <mechanicalReduction>1</mechanicalReduction>
    </actuator>
  </transmission>
  <transmission name="back_left_wheel2base_link_trans">
    <type>transmission_interface/SimpleTransmission</type>
    <joint name="back_left_wheel2base_link">
      <hardwareInterface>hardware_interface/VelocityJointInterface</hardwareInterface>
    </joint>
    <actuator name="back_left_wheel_joint_motor">
      <hardwareInterface>hardware_interface/VelocityJointInterface</hardwareInterface>
      <mechanicalReduction>1</mechanicalReduction>
    </actuator>
  </transmission>
  <gazebo>
    <plugin filename="libgazebo_ros_control.so" name="gazebo_ros_control">
      <robotNamespace>/my_car</robotNamespace>
      <robotParam>robot_description</robotParam>
      <robotSimType>gazebo_ros_control/DefaultRobotHWSim</robotSimType>
      <legacyModeNS>true</legacyModeNS>
    </plugin>
  </gazebo>
  <gazebo>
    <plugin filename="libgazebo_ros_joint_state_publisher.so" name="joint_state_publisher">
      <jointName>front_right_wheel_joint2base_link, 
                       front_left_wheel_joint2base_link, 
                       back_right_wheel2base_link, 
                       back_left_wheel2base_link, 
                       front_left_wheel2front_left_wheel_joint,
                       front_right_wheel2front_right_wheel_joint
            </jointName>
      <updateRate>50.0</updateRate>
      <robotNamespace>/my_car</robotNamespace>
      <alwaysOn>true</alwaysOn>
    </plugin>
  </gazebo>
</robot>

