<?xml version="1.0" ?>
<!-- =================================================================================== -->
<!-- |    This document was autogenerated by xacro from my_car_1.urdf.xacro            | -->
<!-- |    EDITING THIS FILE BY HAND IS NOT RECOMMENDED                                 | -->
<!-- =================================================================================== -->
<!-- 按照先后顺序组合my_car -->
<robot name="my_car">
  <!-- 宏:黑色设置 -->
  <material name="black">
    <color rgba="0.0 0.0 0.0 1.0"/>
  </material>
  <!-- 质量  -->
  <!-- footprint -->
  <link name="base_footprint">
    <visual>
      <geometry>
        <sphere radius="0.001"/>
      </geometry>
    </visual>
  </link>
  <gazebo reference="base_footprint">
    <turnGravityOff>false</turnGravityOff>
    <!--关闭重力-->
  </gazebo>
  <!-- 底盘 -->
  <link name="base_link">
    <visual>
      <geometry>
        <box size="0.15 0.25 0.06"/>
      </geometry>
      <origin rpy="0 0 0" xyz="0 0 0"/>
      <material name="yellow">
        <color rgba="0.5 0.3 0.0 0.5"/>
      </material>
    </visual>
    <collision>
      <geometry>
        <box size="0.15 0.25 0.06"/>
      </geometry>
      <origin rpy="0 0 0" xyz="0 0 0"/>
    </collision>
    <inertial>
      <mass value="5"/>
      <inertia ixx="0.010875000000000001" ixy="0" ixz="0" iyy="0.03541666666666666" iyz="0" izz="0.02754166666666667"/>
    </inertial>
  </link>
  <joint name="base_link2base_footprint" type="fixed">
    <parent link="base_footprint"/>
    <child link="base_link"/>
    <origin xyz="0 0 0.06"/>
  </joint>
  <gazebo reference="base_link">
    <material>Gazebo/Yellow</material>
  </gazebo>
  <link name="back_left_wheel">
    <visual>
      <geometry>
        <cylinder length="0.04" radius="0.03"/>
      </geometry>
      <origin rpy="1.5707963 0.0 0.0" xyz="0.0 0.0 0.0"/>
      <material name="black"/>
    </visual>
    <collision>
      <geometry>
        <cylinder length="0.04" radius="0.03"/>
      </geometry>
      <origin rpy="1.5707963 0.0 0.0" xyz="0.0 0.0 0.0"/>
    </collision>
    <inertial>
      <mass value="0.5"/>
      <inertia ixx="0.00017916666666666667" ixy="0" ixz="0" iyy="0.00017916666666666667" iyz="0" izz="0.000225"/>
    </inertial>
  </link>
  <joint name="back_left_wheel2base_link" type="continuous">
    <parent link="base_link"/>
    <child link="back_left_wheel"/>
    <origin xyz="-0.045 0.115 -0.030"/>
    <axis xyz="0 1 0"/>
    <dynamics damping="0.0"/>
    <limit effort="100" velocity="100"/>
    <joint_properties damping="0.0" friction="0.0"/>
  </joint>
  <gazebo reference="back_left_wheel">
    <material>Gazebo/Red</material>
  </gazebo>
  <link name="back_right_wheel">
    <visual>
      <geometry>
        <cylinder length="0.04" radius="0.03"/>
      </geometry>
      <origin rpy="1.5707963 0.0 0.0" xyz="0.0 0.0 0.0"/>
      <material name="black"/>
    </visual>
    <collision>
      <geometry>
        <cylinder length="0.04" radius="0.03"/>
      </geometry>
      <origin rpy="1.5707963 0.0 0.0" xyz="0.0 0.0 0.0"/>
    </collision>
    <inertial>
      <mass value="0.5"/>
      <inertia ixx="0.00017916666666666667" ixy="0" ixz="0" iyy="0.00017916666666666667" iyz="0" izz="0.000225"/>
    </inertial>
  </link>
  <joint name="back_right_wheel2base_link" type="continuous">
    <parent link="base_link"/>
    <child link="back_right_wheel"/>
    <origin xyz="-0.045 -0.115 -0.030"/>
    <axis xyz="0 1 0"/>
    <dynamics damping="0.0"/>
    <limit effort="100" velocity="100"/>
    <joint_properties damping="0.0" friction="0.0"/>
  </joint>
  <gazebo reference="back_right_wheel">
    <material>Gazebo/Red</material>
  </gazebo>
  <!-- 转向关节 -->
  <link name="front_left_wheel_joint">
    <visual>
      <geometry>
        <sphere radius="0.01"/>
      </geometry>
      <origin rpy="0.0 0.0 0.0" xyz="0.0 0.0 0.0"/>
      <material name="black"/>
    </visual>
    <collision>
      <geometry>
        <sphere radius="0.01"/>
      </geometry>
      <origin rpy="0.0 0.0 0.0" xyz="0.0 0.0 0.0"/>
    </collision>
    <inertial>
      <mass value="0.3"/>
      <inertia ixx="1.2e-05" ixy="0" ixz="0" iyy="1.2e-05" iyz="0" izz="1.2e-05"/>
    </inertial>
  </link>
  <joint name="front_left_wheel_joint2base_link" type="revolute">
    <parent link="base_link"/>
    <child link="front_left_wheel_joint"/>
    <origin xyz="0.045 0.115 0.0"/>
    <axis xyz="0 0 1"/>
    <dynamics damping="0.0"/>
    <limit effort="2.5" lower="-0.785" upper="0.785" velocity="10"/>
    <joint_properties damping="20.0" friction="20.0"/>
  </joint>
  <gazebo reference="front_left_wheel_joint">
    <material>Gazebo/Black</material>
  </gazebo>
  <!--转向轮-->
  <link name="front_left_wheel">
    <visual>
      <geometry>
        <cylinder length="0.04" radius="0.03"/>
      </geometry>
      <origin rpy="1.5707963 0.0 0.0" xyz="0.0 0.0 0.0"/>
      <material name="black"/>
    </visual>
    <collision>
      <geometry>
        <cylinder length="0.04" radius="0.03"/>
      </geometry>
      <origin rpy="1.5707963 0.0 0.0" xyz="0.0 0.0 0.0"/>
    </collision>
    <inertial>
      <mass value="0.5"/>
      <inertia ixx="0.00017916666666666667" ixy="0" ixz="0" iyy="0.00017916666666666667" iyz="0" izz="0.000225"/>
    </inertial>
  </link>
  <joint name="front_left_wheel2front_left_wheel_joint" type="continuous">
    <parent link="front_left_wheel_joint"/>
    <child link="front_left_wheel"/>
    <origin xyz="0 0 -0.030"/>
    <axis xyz="0 1 0"/>
    <dynamics damping="0.0"/>
    <limit effort="100" velocity="100"/>
    <joint_properties damping="0.0" friction="0.0"/>
  </joint>
  <gazebo reference="front_left_wheel">
    <material>Gazebo/Red</material>
  </gazebo>
  <!-- 转向关节 -->
  <link name="front_right_wheel_joint">
    <visual>
      <geometry>
        <sphere radius="0.01"/>
      </geometry>
      <origin rpy="0.0 0.0 0.0" xyz="0.0 0.0 0.0"/>
      <material name="black"/>
    </visual>
    <collision>
      <geometry>
        <sphere radius="0.01"/>
      </geometry>
      <origin rpy="0.0 0.0 0.0" xyz="0.0 0.0 0.0"/>
    </collision>
    <inertial>
      <mass value="0.3"/>
      <inertia ixx="1.2e-05" ixy="0" ixz="0" iyy="1.2e-05" iyz="0" izz="1.2e-05"/>
    </inertial>
  </link>
  <joint name="front_right_wheel_joint2base_link" type="revolute">
    <parent link="base_link"/>
    <child link="front_right_wheel_joint"/>
    <origin xyz="0.045 -0.115 0.0"/>
    <axis xyz="0 0 1"/>
    <dynamics damping="0.0"/>
    <limit effort="2.5" lower="-0.785" upper="0.785" velocity="10"/>
    <joint_properties damping="20.0" friction="20.0"/>
  </joint>
  <gazebo reference="front_right_wheel_joint">
    <material>Gazebo/Black</material>
  </gazebo>
  <!--转向轮-->
  <link name="front_right_wheel">
    <visual>
      <geometry>
        <cylinder length="0.04" radius="0.03"/>
      </geometry>
      <origin rpy="1.5707963 0.0 0.0" xyz="0.0 0.0 0.0"/>
      <material name="black"/>
    </visual>
    <collision>
      <geometry>
        <cylinder length="0.04" radius="0.03"/>
      </geometry>
      <origin rpy="1.5707963 0.0 0.0" xyz="0.0 0.0 0.0"/>
    </collision>
    <inertial>
      <mass value="0.5"/>
      <inertia ixx="0.00017916666666666667" ixy="0" ixz="0" iyy="0.00017916666666666667" iyz="0" izz="0.000225"/>
    </inertial>
  </link>
  <joint name="front_right_wheel2front_right_wheel_joint" type="continuous">
    <parent link="front_right_wheel_joint"/>
    <child link="front_right_wheel"/>
    <origin xyz="0 0 -0.030"/>
    <axis xyz="0 1 0"/>
    <dynamics damping="0.0"/>
    <limit effort="100" velocity="100"/>
    <joint_properties damping="0.0" friction="0.0"/>
  </joint>
  <gazebo reference="front_right_wheel">
    <material>Gazebo/Red</material>
  </gazebo>
</robot>

